// Replace the broken error handling section with:
process.on('uncaughtException', (err) => {
    console.error('Uncaught Exception:', err);
});

process.on('unhandledRejection', (reason, promise) => {
    console.error('Unhandled Rejection at:', promise, 'reason:', reason);
});
